Workbook

Sheet Старт
B2: Трекер арбітражу · Nutra / CPA
B3: Ліміти по гео, щоденна статистика, журнал дій і рішення «вимикати чи чекати» — все рахується автоматично.
B5: ЯК КОРИСТУВАТИСЯ
B6: 1 | C6: «Гео-калькулятор» — по кожному гео внесіть виплату за апрув, план % апруву, цільовий ROI, CR і CTR. EPL, Max CPL, Max CPC, Max CPM і Max ціна апруву порахуються самі.
B7: 2 | C7: «Статистика» — щодня 1 рядок на гео (або гео × кампанія): спенд, покази, кліки, ліди. Апруви — коли прийдуть від ПП; до того дохід рахується прогнозно за планом апруву.
B8: 3 | C8: «Журнал дій» — кожну зміну (запуск, бюджет, креатив, преленд, вимкнення) одним рядком. CPL, ROI і ліди за N днів до та після підтягнуться самі + авто-оцінка «покращило / погіршило».
B9: 4 | C9: «Загальна по днях» і «Зведення по гео» — заповнюються самі. Змінюйте «Початок періоду» або «Від–До», щоб дивитися інший місяць чи тиждень.
B10: 5 | C10: «Спенд без лідів» — таблиця рішень зі скріну + перевірка конкретних адсетів (і коли ліди вже є).
B11: 6 | C11: «Креативи» — трекер тестів креативів з автоматичним вердиктом «масштабувати / в цілі / вимикати».
B13: ПОЗНАЧЕННЯ
C14: 28.00 | E14: Сині клітинки — вводите ви.
C15: 11.20 | E15: Білий текст на темному — формула. Не перезаписуйте.
C16: Масштабувати | E16: Сильно краще цілі — можна масштабувати.
C17: В цілі | E17: CPL ≤ Max CPL — тримати.
C18: Рано судити | E18: Даних ще замало для висновку.
C19: Під питанням | E19: Дивіться уважно — рішення найближчим часом.
C20: Вимикати | E20: Статистично адсет / креатив не в цілі.
C21: Давно треба було | E21: Мали вимкнути раніше — гроші вже злиті.
B23: ГОЛОВНІ ФОРМУЛИ
C24: EPL | E24: Виплата × % апруву | I24: Скільки в середньому заробляєте з 1 ліда.
C25: Max CPL | E25: EPL ÷ (1 + цільовий ROI) | I25: Ліміт CPL для цільового ROI. Беззбиток = EPL.
C26: Max ціна апруву | E26: Виплата ÷ (1 + цільовий ROI) | I26: Скільки можна витратити на 1 апрув.
C27: Max CPC | E27: Max CPL × CR | I27: Максимальна ціна кліка.
C28: Max CPM | E28: Max CPC × CTR × 1000 | I28: Максимальна ціна 1000 показів.
C29: Ціна апруву | E29: Спенд ÷ Апруви | I29: Скільки фактично коштує 1 апрув.
C30: ROI | E30: (Дохід − Спенд) ÷ Спенд | I30: Окупність.
C31: P(0 лідів) | E31: e^(−Спенд ÷ Max CPL) | I31: Шанс, що нормальний адсет не дав лідів.
B33: АРКУШІ
C34: Гео-калькулятор | E34: налаштування гео й ліміти
C35: Статистика | E35: щоденне введення цифр
C36: Журнал дій | E36: що робили і що це дало
C37: Загальна по днях | E37: всі гео разом по днях + графік
C38: Зведення по гео | E38: підсумок і статус кожного гео
C39: Спенд без лідів | E39: вимикати чи чекати
C40: Креативи | E40: тести креативів
C41: Списки | E41: значення випадаючих списків
B43: У «Статистика», «Журнал дій», «Креативи» і в перевірці адсетів — по одному рядку-прикладу. Замініть їх своїми даними. Гео в калькуляторі — теж приклад, впишіть свої.

Sheet Гео-калькулятор
B2: Гео-калькулятор
B3: Сині клітинки — дані по офферу. Все праворуч рахується саме і використовується на всіх інших аркушах.
B5: ВХІДНІ ДАНІ — ЗАПОВНЮЄТЕ ВИ | I5: РОЗРАХУНОК — АВТОМАТИЧНО
B6: Гео | C6: Країна / оффер | D6: Виплата за апрув, $ | E6: % апруву (план) | F6: Цільовий ROI | G6: CR клік → лід | H6: CTR | I6: EPL, $ | J6: CPL беззбитку, $ | K6: Max CPL, $ | L6: Max ціна апруву, $ | M6: Max CPC, $ | N6: Max CPM, $ | O6: Не судити до, $ | P6: Вимикати після (0 лідів), $ | Q6: Нотатки
B7: PL | C7: Польща · суглоби | D7: 28 | E7: 0.4 | F7: 0.3 | G7: 0.05 | H7: 0.02 | I7: =IF(OR($D7="",$E7=""),"",$D7*$E7) -> 11.2 | J7: =IF(I7="","",I7) -> 11.2 | K7: =IF(I7="","",I7/(1+N($F7))) -> 8.6153846 | L7: =IF($D7="","",$D7/(1+N($F7))) -> 21.538462 | M7: =IF(OR(K7="",$G7=""),"",K7*$G7) -> 0.43076923 | N7: =IF(OR(M7="",$H7=""),"",M7*$H7*1000) -> 8.6153846 | O7: =IF(K7="","",-LN('Спенд без лідів'!$H$5)*K7) -> 10.372689 | P7: =IF(K7="","",-LN('Спенд без лідів'!$H$6)*K7) -> 19.837656
B8: RO | C8: Румунія · діабет | D8: 22 | E8: 0.45 | F8: 0.3 | G8: 0.055 | H8: 0.02 | I8: =IF(OR($D8="",$E8=""),"",$D8*$E8) -> 9.9 | J8: =IF(I8="","",I8) -> 9.9 | K8: =IF(I8="","",I8/(1+N($F8))) -> 7.6153846 | L8: =IF($D8="","",$D8/(1+N($F8))) -> 16.923077 | M8: =IF(OR(K8="",$G8=""),"",K8*$G8) -> 0.41884615 | N8: =IF(OR(M8="",$H8=""),"",M8*$H8*1000) -> 8.3769231 | O8: =IF(K8="","",-LN('Спенд без лідів'!$H$5)*K8) -> 9.168716 | P8: =IF(K8="","",-LN('Спенд без лідів'!$H$6)*K8) -> 17.535071
B9: IT | C9: Італія · схуднення | D9: 35 | E9: 0.35 | F9: 0.3 | G9: 0.05 | H9: 0.02 | I9: =IF(OR($D9="",$E9=""),"",$D9*$E9) -> 12.25 | J9: =IF(I9="","",I9) -> 12.25 | K9: =IF(I9="","",I9/(1+N($F9))) -> 9.4230769 | L9: =IF($D9="","",$D9/(1+N($F9))) -> 26.923077 | M9: =IF(OR(K9="",$G9=""),"",K9*$G9) -> 0.47115385 | N9: =IF(OR(M9="",$H9=""),"",M9*$H9*1000) -> 9.4230769 | O9: =IF(K9="","",-LN('Спенд без лідів'!$H$5)*K9) -> 11.345128 | P9: =IF(K9="","",-LN('Спенд без лідів'!$H$6)*K9) -> 21.697436
B10: ES | C10: Іспанія · потенція | D10: 33 | E10: 0.38 | F10: 0.3 | G10: 0.055 | H10: 0.018 | I10: =IF(OR($D10="",$E10=""),"",$D10*$E10) -> 12.54 | J10: =IF(I10="","",I10) -> 12.54 | K10: =IF(I10="","",I10/(1+N($F10))) -> 9.6461538 | L10: =IF($D10="","",$D10/(1+N($F10))) -> 25.384615 | M10: =IF(OR(K10="",$G10=""),"",K10*$G10) -> 0.53053846 | N10: =IF(OR(M10="",$H10=""),"",M10*$H10*1000) -> 9.5496923 | O10: =IF(K10="","",-LN('Спенд без лідів'!$H$5)*K10) -> 11.613707 | P10: =IF(K10="","",-LN('Спенд без лідів'!$H$6)*K10) -> 22.21109
B11: CZ | C11: Чехія · тиск | D11: 26 | E11: 0.4 | F11: 0.3 | G11: 0.05 | H11: 0.019 | I11: =IF(OR($D11="",$E11=""),"",$D11*$E11) -> 10.4 | J11: =IF(I11="","",I11) -> 10.4 | K11: =IF(I11="","",I11/(1+N($F11))) -> 8 | L11: =IF($D11="","",$D11/(1+N($F11))) -> 20 | M11: =IF(OR(K11="",$G11=""),"",K11*$G11) -> 0.4 | N11: =IF(OR(M11="",$H11=""),"",M11*$H11*1000) -> 7.6 | O11: =IF(K11="","",-LN('Спенд без лідів'!$H$5)*K11) -> 9.6317824 | P11: =IF(K11="","",-LN('Спенд без лідів'!$H$6)*K11) -> 18.420681 | Q11: тест з 06.10
B12: BG | C12: Болгарія · суглоби | D12: 20 | E12: 0.42 | F12: 0.3 | G12: 0.06 | H12: 0.024 | I12: =IF(OR($D12="",$E12=""),"",$D12*$E12) -> 8.4 | J12: =IF(I12="","",I12) -> 8.4 | K12: =IF(I12="","",I12/(1+N($F12))) -> 6.4615385 | L12: =IF($D12="","",$D12/(1+N($F12))) -> 15.384615 | M12: =IF(OR(K12="",$G12=""),"",K12*$G12) -> 0.38769231 | N12: =IF(OR(M12="",$H12=""),"",M12*$H12*1000) -> 9.3046154 | O12: =IF(K12="","",-LN('Спенд без лідів'!$H$5)*K12) -> 7.7795166 | P12: =IF(K12="","",-LN('Спенд без лідів'!$H$6)*K12) -> 14.878242
B13: GR | C13: Греція · простатит | D13: 27 | E13: 0.43 | F13: 0.3 | G13: 0.055 | H13: 0.021 | I13: =IF(OR($D13="",$E13=""),"",$D13*$E13) -> 11.61 | J13: =IF(I13="","",I13) -> 11.61 | K13: =IF(I13="","",I13/(1+N($F13))) -> 8.9307692 | L13: =IF($D13="","",$D13/(1+N($F13))) -> 20.769231 | M13: =IF(OR(K13="",$G13=""),"",K13*$G13) -> 0.49119231 | N13: =IF(OR(M13="",$H13=""),"",M13*$H13*1000) -> 10.315038 | O13: =IF(K13="","",-LN('Спенд без лідів'!$H$5)*K13) -> 10.752403 | P13: =IF(K13="","",-LN('Спенд без лідів'!$H$6)*K13) -> 20.563856
B16: ЯК РАХУЄТЬСЯ
B17: EPL | D17: Виплата × % апруву | I17: Скільки в середньому заробляєте з 1 ліда.
B18: CPL беззбитку | D18: дорівнює EPL | I18: Якщо CPL вищий — працюєте в мінус.
B19: Max CPL | D19: EPL ÷ (1 + цільовий ROI) | I19: Ліміт CPL, при якому виходить ваш цільовий ROI.
B20: Max ціна апруву | D20: Виплата ÷ (1 + цільовий ROI) | I20: Скільки можна витратити на 1 апрув.
B21: Max CPC | D21: Max CPL × CR | I21: Максимальна ціна кліка при вашій конверсії ленда.
B22: Max CPM | D22: Max CPC × CTR × 1000 | I22: Максимальна ціна 1000 показів при вашому CTR.
B23: Не судити до | D23: −ln(поріг «Рано судити») × Max CPL | I23: При 30% ≈ 1.2 × Max CPL.
B24: Вимикати після | D24: −ln(поріг «Під питанням») × Max CPL | I24: При 10% ≈ 2.3 × Max CPL без жодного ліда.

Sheet Статистика
B2: Щоденна статистика
B3: 1 рядок = день × гео (можна × кампанія). Апруви вносьте, коли прийдуть від ПП — до того дохід рахується прогнозно за планом апруву з калькулятора.
B5: ВВОДИТЕ ВИ | J5: ТРАФІК — АВТО | Q5: ГРОШІ — АВТО
B6: Дата | C6: Гео | D6: Кампанія / адсет | E6: Спенд, $ | F6: Покази | G6: Кліки | H6: Ліди | I6: Апруви (факт) | J6: CTR | K6: CPC, $ | L6: CPM, $ | M6: CR | N6: CPL, $ | O6: Max CPL, $ | P6: CPL / Max | Q6: Апруви* | R6: % апруву | S6: Ціна апруву, $ | T6: Дохід, $ | U6: Профіт, $ | V6: ROI | W6: Дані
B7: 46296 | C7: PL | D7: PL | суглоби | CBO-1 | E7: 150 | F7: 20000 | G7: 420 | H7: 21 | I7: 8 | J7: =IF($E7="","",IFERROR(G7/F7,"")) -> 0.021 | K7: =IF($E7="","",IFERROR(E7/G7,"")) -> 0.35714286 | L7: =IF($E7="","",IFERROR(E7/F7*1000,"")) -> 7.5 | M7: =IF($E7="","",IFERROR(H7/G7,"")) -> 0.05 | N7: =IF($E7="","",IFERROR(E7/H7,"—")) -> 7.1428571 | O7: =IF($E7="","",IFERROR(INDEX('Гео-калькулятор'!$K$7:$K$13,MATCH($C7,'Гео-калькулятор'!$B$7:$B$13,0)),"")) -> 8.6153846 | P7: =IF($E7="","",IFERROR(N7/O7,"")) -> 0.82908163 | Q7: =IF($E7="","",IF($I7<>"",$I7,N($H7)*IFERROR(INDEX('Гео-калькулятор'!$E$7:$E$13,MATCH($C7,'Гео-калькулятор'!$B$7:$B$13,0)),0))) -> 8 | R7: =IF($E7="","",IFERROR(Q7/H7,"")) -> 0.38095238 | S7: =IF($E7="","",IFERROR(E7/Q7,"—")) -> 18.75 | T7: =IF($E7="","",Q7*IFERROR(INDEX('Гео-калькулятор'!$D$7:$D$13,MATCH($C7,'Гео-калькулятор'!$B$7:$B$13,0)),0)) -> 224 | U7: =IF($E7="","",T7-E7) -> 74 | V7: =IF($E7="","",IFERROR(U7/E7,"")) -> 0.49333333 | W7: =IF($E7="","",IF($I7<>"","факт","прогноз")) -> факт
J8: =IF($E8="","",IFERROR(G8/F8,"")) | K8: =IF($E8="","",IFERROR(E8/G8,"")) | L8: =IF($E8="","",IFERROR(E8/F8*1000,"")) | M8: =IF($E8="","",IFERROR(H8/G8,"")) | N8: =IF($E8="","",IFERROR(E8/H8,"—")) | O8: =IF($E8="","",IFERROR(INDEX('Гео-калькулятор'!$K$7:$K$13,MATCH($C8,'Гео-калькулятор'!$B$7:$B$13,0)),"")) | P8: =IF($E8="","",IFERROR(N8/O8,"")) | Q8: =IF($E8="","",IF($I8<>"",$I8,N($H8)*IFERROR(INDEX('Гео-калькулятор'!$E$7:$E$13,MATCH($C8,'Гео-калькулятор'!$B$7:$B$13,0)),0))) | R8: =IF($E8="","",IFERROR(Q8/H8,"")) | S8: =IF($E8="","",IFERROR(E8/Q8,"—")) | T8: =IF($E8="","",Q8*IFERROR(INDEX('Гео-калькулятор'!$D$7:$D$13,MATCH($C8,'Гео-калькулятор'!$B$7:$B$13,0)),0)) | U8: =IF($E8="","",T8-E8) | V8: =IF($E8="","",IFERROR(U8/E8,"")) | W8: =IF($E8="","",IF($I8<>"","факт","прогноз"))
J9: =IF($E9="","",IFERROR(G9/F9,"")) | K9: =IF($E9="","",IFERROR(E9/G9,"")) | L9: =IF($E9="","",IFERROR(E9/F9*1000,"")) | M9: =IF($E9="","",IFERROR(H9/G9,"")) | N9: =IF($E9="","",IFERROR(E9/H9,"—")) | O9: =IF($E9="","",IFERROR(INDEX('Гео-калькулятор'!$K$7:$K$13,MATCH($C9,'Гео-калькулятор'!$B$7:$B$13,0)),"")) | P9: =IF($E9="","",IFERROR(N9/O9,"")) | Q9: =IF($E9="","",IF($I9<>"",$I9,N($H9)*IFERROR(INDEX('Гео-калькулятор'!$E$7:$E$13,MATCH($C9,'Гео-калькулятор'!$B$7:$B$13,0)),0))) | R9: =IF($E9="","",IFERROR(Q9/H9,"")) | S9: =IF($E9="","",IFERROR(E9/Q9,"—")) | T9: =IF($E9="","",Q9*IFERROR(INDEX('Гео-калькулятор'!$D$7:$D$13,MATCH($C9,'Гео-калькулятор'!$B$7:$B$13,0)),0)) | U9: =IF($E9="","",T9-E9) | V9: =IF($E9="","",IFERROR(U9/E9,"")) | W9: =IF($E9="","",IF($I9<>"","факт","прогноз"))
J10: =IF($E10="","",IFERROR(G10/F10,"")) | K10: =IF($E10="","",IFERROR(E10/G10,"")) | L10: =IF($E10="","",IFERROR(E10/F10*1000,"")) | M10: =IF($E10="","",IFERROR(H10/G10,"")) | N10: =IF($E10="","",IFERROR(E10/H10,"—")) | O10: =IF($E10="","",IFERROR(INDEX('Гео-калькулятор'!$K$7:$K$13,MATCH($C10,'Гео-калькулятор'!$B$7:$B$13,0)),"")) | P10: =IF($E10="","",IFERROR(N10/O10,"")) | Q10: =IF($E10="","",IF($I10<>"",$I10,N($H10)*IFERROR(INDEX('Гео-калькулятор'!$E$7:$E$13,MATCH($C10,'Гео-калькулятор'!$B$7:$B$13,0)),0))) | R10: =IF($E10="","",IFERROR(Q10/H10,"")) | S10: =IF($E10="","",IFERROR(E10/Q10,"—")) | T10: =IF($E10="","",Q10*IFERROR(INDEX('Гео-калькулятор'!$D$7:$D$13,MATCH($C10,'Гео-калькулятор'!$B$7:$B$13,0)),0)) | U10: =IF($E10="","",T10-E10) | V10: =IF($E10="","",IFERROR(U10/E10,"")) | W10: =IF($E10="","",IF($I10<>"","факт","прогноз"))
J11: =IF($E11="","",IFERROR(G11/F11,"")) | K11: =IF($E11="","",IFERROR(E11/G11,"")) | L11: =IF($E11="","",IFERROR(E11/F11*1000,"")) | M11: =IF($E11="","",IFERROR(H11/G11,"")) | N11: =IF($E11="","",IFERROR(E11/H11,"—")) | O11: =IF($E11="","",IFERROR(INDEX('Гео-калькулятор'!$K$7:$K$13,MATCH($C11,'Гео-калькулятор'!$B$7:$B$13,0)),"")) | P11: =IF($E11="","",IFERROR(N11/O11,"")) | Q11: =IF($E11="","",IF($I11<>"",$I11,N($H11)*IFERROR(INDEX('Гео-калькулятор'!$E$7:$E$13,MATCH($C11,'Гео-калькулятор'!$B$7:$B$13,0)),0))) | R11: =IF($E11="","",IFERROR(Q11/H11,"")) | S11: =IF($E11="","",IFERROR(E11/Q11,"—")) | T11: =IF($E11="","",Q11*IFERROR(INDEX('Гео-калькулятор'!$D$7:$D$13,MATCH($C11,'Гео-калькулятор'!$B$7:$B$13,0)),0)) | U11: =IF($E11="","",T11-E11) | V11: =IF($E11="","",IFERROR(U11/E11,"")) | W11: =IF($E11="","",IF($I11<>"","факт","прогноз"))
J12: =IF($E12="","",IFERROR(G12/F12,"")) | K12: =IF($E12="","",IFERROR(E12/G12,"")) | L12: =IF($E12="","",IFERROR(E12/F12*1000,"")) | M12: =IF($E12="","",IFERROR(H12/G12,"")) | N12: =IF($E12="","",IFERROR(E12/H12,"—")) | O12: =IF($E12="","",IFERROR(INDEX('Гео-калькулятор'!$K$7:$K$13,MATCH($C12,'Гео-калькулятор'!$B$7:$B$13,0)),"")) | P12: =IF($E12="","",IFERROR(N12/O12,"")) | Q12: =IF($E12="","",IF($I12<>"",$I12,N($H12)*IFERROR(INDEX('Гео-калькулятор'!$E$7:$E$13,MATCH($C12,'Гео-калькулятор'!$B$7:$B$13,0)),0))) | R12: =IF($E12="","",IFERROR(Q12/H12,"")) | S12: =IF($E12="","",IFERROR(E12/Q12,"—")) | T12: =IF($E12="","",Q12*IFERROR(INDEX('Гео-калькулятор'!$D$7:$D$13,MATCH($C12,'Гео-калькулятор'!$B$7:$B$13,0)),0)) | U12: =IF($E12="","",T12-E12) | V12: =IF($E12="","",IFERROR(U12/E12,"")) | W12: =IF($E12="","",IF($I12<>"","факт","прогноз"))
J13: =IF($E13="","",IFERROR(G13/F13,"")) | K13: =IF($E13="","",IFERROR(E13/G13,"")) | L13: =IF($E13="","",IFERROR(E13/F13*1000,"")) | M13: =IF($E13="","",IFERROR(H13/G13,"")) | N13: =IF($E13="","",IFERROR(E13/H13,"—")) | O13: =IF($E13="","",IFERROR(INDEX('Гео-калькулятор'!$K$7:$K$13,MATCH($C13,'Гео-калькулятор'!$B$7:$B$13,0)),"")) | P13: =IF($E13="","",IFERROR(N13/O13,"")) | Q13: =IF($E13="","",IF($I13<>"",$I13,N($H13)*IFERROR(INDEX('Гео-калькулятор'!$E$7:$E$13,MATCH($C13,'Гео-калькулятор'!$B$7:$B$13,0)),0))) | R13: =IF($E13="","",IFERROR(Q13/H13,"")) | S13: =IF($E13="","",IFERROR(E13/Q13,"—")) | T13: =IF($E13="","",Q13*IFERROR(INDEX('Гео-калькулятор'!$D$7:$D$13,MATCH($C13,'Гео-калькулятор'!$B$7:$B$13,0)),0)) | U13: =IF($E13="","",T13-E13) | V13: =IF($E13="","",IFERROR(U13/E13,"")) | W13: =IF($E13="","",IF($I13<>"","факт","прогноз"))
J14: =IF($E14="","",IFERROR(G14/F14,"")) | K14: =IF($E14="","",IFERROR(E14/G14,"")) | L14: =IF($E14="","",IFERROR(E14/F14*1000,"")) | M14: =IF($E14="","",IFERROR(H14/G14,"")) | N14: =IF($E14="","",IFERROR(E14/H14,"—")) | O14: =IF($E14="","",IFERROR(INDEX('Гео-калькулятор'!$K$7:$K$13,MATCH($C14,'Гео-калькулятор'!$B$7:$B$13,0)),"")) | P14: =IF($E14="","",IFERROR(N14/O14,"")) | Q14: =IF($E14="","",IF($I14<>"",$I14,N($H14)*IFERROR(INDEX('Гео-калькулятор'!$E$7:$E$13,MATCH($C14,'Гео-калькулятор'!$B$7:$B$13,0)),0))) | R14: =IF($E14="","",IFERROR(Q14/H14,"")) | S14: =IF($E14="","",IFERROR(E14/Q14,"—")) | T14: =IF($E14="","",Q14*IFERROR(INDEX('Гео-калькулятор'!$D$7:$D$13,MATCH($C14,'Гео-калькулятор'!$B$7:$B$13,0)),0)) | U14: =IF($E14="","",T14-E14) | V14: =IF($E14="","",IFERROR(U14/E14,"")) | W14: =IF($E14="","",IF($I14<>"","факт","прогноз"))
J15: =IF($E15="","",IFERROR(G15/F15,"")) | K15: =IF($E15="","",IFERROR(E15/G15,"")) | L15: =IF($E15="","",IFERROR(E15/F15*1000,"")) | M15: =IF($E15="","",IFERROR(H15/G15,"")) | N15: =IF($E15="","",IFERROR(E15/H15,"—")) | O15: =IF($E15="","",IFERROR(INDEX('Гео-калькулятор'!$K$7:$K$13,MATCH($C15,'Гео-калькулятор'!$B$7:$B$13,0)),"")) | P15: =IF($E15="","",IFERROR(N15/O15,"")) | Q15: =IF($E15="","",IF($I15<>"",$I15,N($H15)*IFERROR(INDEX('Гео-калькулятор'!$E$7:$E$13,MATCH($C15,'Гео-калькулятор'!$B$7:$B$13,0)),0))) | R15: =IF($E15="","",IFERROR(Q15/H15,"")) | S15: =IF($E15="","",IFERROR(E15/Q15,"—")) | T15: =IF($E15="","",Q15*IFERROR(INDEX('Гео-калькулятор'!$D$7:$D$13,MATCH($C15,'Гео-калькулятор'!$B$7:$B$13,0)),0)) | U15: =IF($E15="","",T15-E15) | V15: =IF($E15="","",IFERROR(U15/E15,"")) | W15: =IF($E15="","",IF($I15<>"","факт","прогноз"))
J16: =IF($E16="","",IFERROR(G16/F16,"")) | K16: =IF($E16="","",IFERROR(E16/G16,"")) | L16: =IF($E16="","",IFERROR(E16/F16*1000,"")) | M16: =IF($E16="","",IFERROR(H16/G16,"")) | N16: =IF($E16="","",IFERROR(E16/H16,"—")) | O16: =IF($E16="","",IFERROR(INDEX('Гео-калькулятор'!$K$7:$K$13,MATCH($C16,'Гео-калькулятор'!$B$7:$B$13,0)),"")) | P16: =IF($E16="","",IFERROR(N16/O16,"")) | Q16: =IF($E16="","",IF($I16<>"",$I16,N($H16)*IFERROR(INDEX('Гео-калькулятор'!$E$7:$E$13,MATCH($C16,'Гео-калькулятор'!$B$7:$B$13,0)),0))) | R16: =IF($E16="","",IFERROR(Q16/H16,"")) | S16: =IF($E16="","",IFERROR(E16/Q16,"—")) | T16: =IF($E16="","",Q16*IFERROR(INDEX('Гео-калькулятор'!$D$7:$D$13,MATCH($C16,'Гео-калькулятор'!$B$7:$B$13,0)),0)) | U16: =IF($E16="","",T16-E16) | V16: =IF($E16="","",IFERROR(U16/E16,"")) | W16: =IF($E16="","",IF($I16<>"","факт","прогноз"))
J17: =IF($E17="","",IFERROR(G17/F17,"")) | K17: =IF($E17="","",IFERROR(E17/G17,"")) | L17: =IF($E17="","",IFERROR(E17/F17*1000,"")) | M17: =IF($E17="","",IFERROR(H17/G17,"")) | N17: =IF($E17="","",IFERROR(E17/H17,"—")) | O17: =IF($E17="","",IFERROR(INDEX('Гео-калькулятор'!$K$7:$K$13,MATCH($C17,'Гео-калькулятор'!$B$7:$B$13,0)),"")) | P17: =IF($E17="","",IFERROR(N17/O17,"")) | Q17: =IF($E17="","",IF($I17<>"",$I17,N($H17)*IFERROR(INDEX('Гео-калькулятор'!$E$7:$E$13,MATCH($C17,'Гео-калькулятор'!$B$7:$B$13,0)),0))) | R17: =IF($E17="","",IFERROR(Q17/H17,"")) | S17: =IF($E17="","",IFERROR(E17/Q17,"—")) | T17: =IF($E17="","",Q17*IFERROR(INDEX('Гео-калькулятор'!$D$7:$D$13,MATCH($C17,'Гео-калькулятор'!$B$7:$B$13,0)),0)) | U17: =IF($E17="","",T17-E17) | V17: =IF($E17="","",IFERROR(U17/E17,"")) | W17: =IF($E17="","",IF($I17<>"","факт","прогноз"))
J18: =IF($E18="","",IFERROR(G18/F18,"")) | K18: =IF($E18="","",IFERROR(E18/G18,"")) | L18: =IF($E18="","",IFERROR(E18/F18*1000,"")) | M18: =IF($E18="","",IFERROR(H18/G18,"")) | N18: =IF($E18="","",IFERROR(E18/H18,"—")) | O18: =IF($E18="","",IFERROR(INDEX('Гео-калькулятор'!$K$7:$K$13,MATCH($C18,'Гео-калькулятор'!$B$7:$B$13,0)),"")) | P18: =IF($E18="","",IFERROR(N18/O18,"")) | Q18: =IF($E18="","",IF($I18<>"",$I18,N($H18)*IFERROR(INDEX('Гео-калькулятор'!$E$7:$E$13,MATCH($C18,'Гео-калькулятор'!$B$7:$B$13,0)),0))) | R18: =IF($E18="","",IFERROR(Q18/H18,"")) | S18: =IF($E18="","",IFERROR(E18/Q18,"—")) | T18: =IF($E18="","",Q18*IFERROR(INDEX('Гео-калькулятор'!$D$7:$D$13,MATCH($C18,'Гео-калькулятор'!$B$7:$B$13,0)),0)) | U18: =IF($E18="","",T18-E18) | V18: =IF($E18="","",IFERROR(U18/E18,"")) | W18: =IF($E18="","",IF($I18<>"","факт","прогноз"))
J19: =IF($E19="","",IFERROR(G19/F19,"")) | K19: =IF($E19="","",IFERROR(E19/G19,"")) | L19: =IF($E19="","",IFERROR(E19/F19*1000,"")) | M19: =IF($E19="","",IFERROR(H19/G19,"")) | N19: =IF($E19="","",IFERROR(E19/H19,"—")) | O19: =IF($E19="","",IFERROR(INDEX('Гео-калькулятор'!$K$7:$K$13,MATCH($C19,'Гео-калькулятор'!$B$7:$B$13,0)),"")) | P19: =IF($E19="","",IFERROR(N19/O19,"")) | Q19: =IF($E19="","",IF($I19<>"",$I19,N($H19)*IFERROR(INDEX('Гео-калькулятор'!$E$7:$E$13,MATCH($C19,'Гео-калькулятор'!$B$7:$B$13,0)),0))) | R19: =IF($E19="","",IFERROR(Q19/H19,"")) | S19: =IF($E19="","",IFERROR(E19/Q19,"—")) | T19: =IF($E19="","",Q19*IFERROR(INDEX('Гео-калькулятор'!$D$7:$D$13,MATCH($C19,'Гео-калькулятор'!$B$7:$B$13,0)),0)) | U19: =IF($E19="","",T19-E19) | V19: =IF($E19="","",IFERROR(U19/E19,"")) | W19: =IF($E19="","",IF($I19<>"","факт","прогноз"))
... J1006: =IF($E1006="","",IFERROR(G1006/F1006,"")) | K1006: =IF($E1006="","",IFERROR(E1006/G1006,"")) | L1006: =IF($E1006="","",IFERROR(E1006/F1006*1000,"")) | M1006: =IF($E1006="","",IFERROR(H1006/G1006,"")) | N1006: =IF($E1006="","",IFERROR(E1006/H1006,"—")) | O1006: =IF($E1006="","",IFERROR(INDEX('Гео-калькулятор'!$K$7:$K$13,MATCH($C1006,'Гео-калькулятор'!$B$7:$B$13,0)),"")) | P1006: =IF($E1006="","",IFERROR(N1006/O1006,"")) | Q1006: =IF($E1006="","",IF($I1006<>"",$I1006,N($H1006)*IFERROR(INDEX('Гео-калькулятор'!$E$7:$E$13,MATCH($C1006,'Гео-калькулятор'!$B$7:$B$13,0)),0))) | R1006: =IF($E1006="","",IFERROR(Q1006/H1006,"")) | S1006: =IF($E1006="","",IFERROR(E1006/Q1006,"—")) | T1006: =IF($E1006="","",Q1006*IFERROR(INDEX('Гео-калькулятор'!$D$7:$D$13,MATCH($C1006,'Гео-калькулятор'!$B$7:$B$13,0)),0)) | U1006: =IF($E1006="","",T1006-E1006) | V1006: =IF($E1006="","",IFERROR(U1006/E1006,"")) | W1006: =IF($E1006="","",IF($I1006<>"","факт","прогноз"))

Sheet Журнал дій
B2: Журнал дій
B3: Кожна зміна = 1 рядок. Метрики за N днів ДО і ПІСЛЯ дії підтягуються зі «Статистики» самі — видно, що до чого призвело.
B5: Вікно, днів | D5: 3 | E5: Поріг зміни CPL | F5: 0.1 | G5: ДО = N днів перед датою дії, ПІСЛЯ = N днів після (день дії не рахується). Дані — по гео (і по кампанії, якщо вказана і так само записана в «Статистиці»). Порожнє гео = всі гео.
B7: ЩО ЗРОБИЛИ — ЗАПОВНЮЄТЕ ВИ | I7: ЩО ЦЕ ДАЛО — АВТОМАТИЧНО | Q7: ВИСНОВОК
B8: № | C8: Дата | D8: Гео | E8: Кампанія / адсет | F8: Тип дії | G8: Що зроблено | H8: Гіпотеза — чому | I8: CPL до, $ | J8: CPL після, $ | K8: Δ CPL | L8: ROI до | M8: ROI після | N8: Лідів/день до | O8: Лідів/день після | P8: Авто-оцінка | Q8: Висновок / наступний крок | S8: Спенд до | T8: Ліди до | U8: Дохід до | V8: Спенд після | W8: Ліди після | X8: Дохід після
B9: =IF($C9="","",ROW()-8) -> 1 | C9: 46299 | D9: ES | F9: Новий преленд / ленд | G9: Замінив преленд на новий (історія лікаря) | H9: Старий преленд: CR 4%, CPL вище Max | I9: =IF($C9="","",IFERROR(S9/T9,"—")) -> — | J9: =IF($C9="","",IFERROR(V9/W9,"—")) -> — | K9: =IF($C9="","",IFERROR(J9/I9-1,"")) | L9: =IF($C9="","",IFERROR((U9-S9)/S9,"—")) -> — | M9: =IF($C9="","",IFERROR((X9-V9)/V9,"—")) -> — | N9: =IF($C9="","",T9/$D$5) -> 0 | O9: =IF($C9="","",W9/$D$5) -> 0 | P9: =IF($C9="","",IF(MAX(Статистика!$B$7:$B$1006)<$C9+$D$5,"Чекаємо даних",IF(S9=0,"Новий (без бази)",IF(OR(T9=0,W9=0),"Мало даних",IF(K9<=-$F$5,"Покращило",IF(K9>=$F$5,"Погіршило","Без змін")))))) -> Чекаємо даних | Q9: Преленд робочий — лишаємо, тестуємо його на IT | S9: =IF($C9="","",SUMIFS(Статистика!$E$7:$E$1006,Статистика!$B$7:$B$1006,">="&($C9-$D$5),Статистика!$B$7:$B$1006,"<="&($C9-1),Статистика!$C$7:$C$1006,IF($D9="","<>§",$D9),Статистика!$D$7:$D$1006,IF($E9="","<>§",$E9))) -> 0 | T9: =IF($C9="","",SUMIFS(Статистика!$H$7:$H$1006,Статистика!$B$7:$B$1006,">="&($C9-$D$5),Статистика!$B$7:$B$1006,"<="&($C9-1),Статистика!$C$7:$C$1006,IF($D9="","<>§",$D9),Статистика!$D$7:$D$1006,IF($E9="","<>§",$E9))) -> 0 | U9: =IF($C9="","",SUMIFS(Статистика!$T$7:$T$1006,Статистика!$B$7:$B$1006,">="&($C9-$D$5),Статистика!$B$7:$B$1006,"<="&($C9-1),Статистика!$C$7:$C$1006,IF($D9="","<>§",$D9),Статистика!$D$7:$D$1006,IF($E9="","<>§",$E9))) -> 0 | V9: =IF($C9="","",SUMIFS(Статистика!$E$7:$E$1006,Статистика!$B$7:$B$1006,">="&($C9+1),Статистика!$B$7:$B$1006,"<="&($C9+$D$5),Статистика!$C$7:$C$1006,IF($D9="","<>§",$D9),Статистика!$D$7:$D$1006,IF($E9="","<>§",$E9))) -> 0 | W9: =IF($C9="","",SUMIFS(Статистика!$H$7:$H$1006,Статистика!$B$7:$B$1006,">="&($C9+1),Статистика!$B$7:$B$1006,"<="&($C9+$D$5),Статистика!$C$7:$C$1006,IF($D9="","<>§",$D9),Статистика!$D$7:$D$1006,IF($E9="","<>§",$E9))) -> 0 | X9: =IF($C9="","",SUMIFS(Статистика!$T$7:$T$1006,Статистика!$B$7:$B$1006,">="&($C9+1),Статистика!$B$7:$B$1006,"<="&($C9+$D$5),Статистика!$C$7:$C$1006,IF($D9="","<>§",$D9),Статистика!$D$7:$D$1006,IF($E9="","<>§",$E9))) -> 0
B10: =IF($C10="","",ROW()-8) | I10: =IF($C10="","",IFERROR(S10/T10,"—")) | J10: =IF($C10="","",IFERROR(V10/W10,"—")) | K10: =IF($C10="","",IFERROR(J10/I10-1,"")) | L10: =IF($C10="","",IFERROR((U10-S10)/S10,"—")) | M10: =IF($C10="","",IFERROR((X10-V10)/V10,"—")) | N10: =IF($C10="","",T10/$D$5) | O10: =IF($C10="","",W10/$D$5) | P10: =IF($C10="","",IF(MAX(Статистика!$B$7:$B$1006)<$C10+$D$5,"Чекаємо даних",IF(S10=0,"Новий (без бази)",IF(OR(T10=0,W10=0),"Мало даних",IF(K10<=-$F$5,"Покращило",IF(K10>=$F$5,"Погіршило","Без змін")))))) | S10: =IF($C10="","",SUMIFS(Статистика!$E$7:$E$1006,Статистика!$B$7:$B$1006,">="&($C10-$D$5),Статистика!$B$7:$B$1006,"<="&($C10-1),Статистика!$C$7:$C$1006,IF($D10="","<>§",$D10),Статистика!$D$7:$D$1006,IF($E10="","<>§",$E10))) | T10: =IF($C10="","",SUMIFS(Статистика!$H$7:$H$1006,Статистика!$B$7:$B$1006,">="&($C10-$D$5),Статистика!$B$7:$B$1006,"<="&($C10-1),Статистика!$C$7:$C$1006,IF($D10="","<>§",$D10),Статистика!$D$7:$D$1006,IF($E10="","<>§",$E10))) | U10: =IF($C10="","",SUMIFS(Статистика!$T$7:$T$1006,Статистика!$B$7:$B$1006,">="&($C10-$D$5),Статистика!$B$7:$B$1006,"<="&($C10-1),Статистика!$C$7:$C$1006,IF($D10="","<>§",$D10),Статистика!$D$7:$D$1006,IF($E10="","<>§",$E10))) | V10: =IF($C10="","",SUMIFS(Статистика!$E$7:$E$1006,Статистика!$B$7:$B$1006,">="&($C10+1),Статистика!$B$7:$B$1006,"<="&($C10+$D$5),Статистика!$C$7:$C$1006,IF($D10="","<>§",$D10),Статистика!$D$7:$D$1006,IF($E10="","<>§",$E10))) | W10: =IF($C10="","",SUMIFS(Статистика!$H$7:$H$1006,Статистика!$B$7:$B$1006,">="&($C10+1),Статистика!$B$7:$B$1006,"<="&($C10+$D$5),Статистика!$C$7:$C$1006,IF($D10="","<>§",$D10),Статистика!$D$7:$D$1006,IF($E10="","<>§",$E10))) | X10: =IF($C10="","",SUMIFS(Статистика!$T$7:$T$1006,Статистика!$B$7:$B$1006,">="&($C10+1),Статистика!$B$7:$B$1006,"<="&($C10+$D$5),Статистика!$C$7:$C$1006,IF($D10="","<>§",$D10),Статистика!$D$7:$D$1006,IF($E10="","<>§",$E10)))
B11: =IF($C11="","",ROW()-8) | I11: =IF($C11="","",IFERROR(S11/T11,"—")) | J11: =IF($C11="","",IFERROR(V11/W11,"—")) | K11: =IF($C11="","",IFERROR(J11/I11-1,"")) | L11: =IF($C11="","",IFERROR((U11-S11)/S11,"—")) | M11: =IF($C11="","",IFERROR((X11-V11)/V11,"—")) | N11: =IF($C11="","",T11/$D$5) | O11: =IF($C11="","",W11/$D$5) | P11: =IF($C11="","",IF(MAX(Статистика!$B$7:$B$1006)<$C11+$D$5,"Чекаємо даних",IF(S11=0,"Новий (без бази)",IF(OR(T11=0,W11=0),"Мало даних",IF(K11<=-$F$5,"Покращило",IF(K11>=$F$5,"Погіршило","Без змін")))))) | S11: =IF($C11="","",SUMIFS(Статистика!$E$7:$E$1006,Статистика!$B$7:$B$1006,">="&($C11-$D$5),Статистика!$B$7:$B$1006,"<="&($C11-1),Статистика!$C$7:$C$1006,IF($D11="","<>§",$D11),Статистика!$D$7:$D$1006,IF($E11="","<>§",$E11))) | T11: =IF($C11="","",SUMIFS(Статистика!$H$7:$H$1006,Статистика!$B$7:$B$1006,">="&($C11-$D$5),Статистика!$B$7:$B$1006,"<="&($C11-1),Статистика!$C$7:$C$1006,IF($D11="","<>§",$D11),Статистика!$D$7:$D$1006,IF($E11="","<>§",$E11))) | U11: =IF($C11="","",SUMIFS(Статистика!$T$7:$T$1006,Статистика!$B$7:$B$1006,">="&($C11-$D$5),Статистика!$B$7:$B$1006,"<="&($C11-1),Статистика!$C$7:$C$1006,IF($D11="","<>§",$D11),Статистика!$D$7:$D$1006,IF($E11="","<>§",$E11))) | V11: =IF($C11="","",SUMIFS(Статистика!$E$7:$E$1006,Статистика!$B$7:$B$1006,">="&($C11+1),Статистика!$B$7:$B$1006,"<="&($C11+$D$5),Статистика!$C$7:$C$1006,IF($D11="","<>§",$D11),Статистика!$D$7:$D$1006,IF($E11="","<>§",$E11))) | W11: =IF($C11="","",SUMIFS(Статистика!$H$7:$H$1006,Статистика!$B$7:$B$1006,">="&($C11+1),Статистика!$B$7:$B$1006,"<="&($C11+$D$5),Статистика!$C$7:$C$1006,IF($D11="","<>§",$D11),Статистика!$D$7:$D$1006,IF($E11="","<>§",$E11))) | X11: =IF($C11="","",SUMIFS(Статистика!$T$7:$T$1006,Статистика!$B$7:$B$1006,">="&($C11+1),Статистика!$B$7:$B$1006,"<="&($C11+$D$5),Статистика!$C$7:$C$1006,IF($D11="","<>§",$D11),Статистика!$D$7:$D$1006,IF($E11="","<>§",$E11)))
B12: =IF($C12="","",ROW()-8) | I12: =IF($C12="","",IFERROR(S12/T12,"—")) | J12: =IF($C12="","",IFERROR(V12/W12,"—")) | K12: =IF($C12="","",IFERROR(J12/I12-1,"")) | L12: =IF($C12="","",IFERROR((U12-S12)/S12,"—")) | M12: =IF($C12="","",IFERROR((X12-V12)/V12,"—")) | N12: =IF($C12="","",T12/$D$5) | O12: =IF($C12="","",W12/$D$5) | P12: =IF($C12="","",IF(MAX(Статистика!$B$7:$B$1006)<$C12+$D$5,"Чекаємо даних",IF(S12=0,"Новий (без бази)",IF(OR(T12=0,W12=0),"Мало даних",IF(K12<=-$F$5,"Покращило",IF(K12>=$F$5,"Погіршило","Без змін")))))) | S12: =IF($C12="","",SUMIFS(Статистика!$E$7:$E$1006,Статистика!$B$7:$B$1006,">="&($C12-$D$5),Статистика!$B$7:$B$1006,"<="&($C12-1),Статистика!$C$7:$C$1006,IF($D12="","<>§",$D12),Статистика!$D$7:$D$1006,IF($E12="","<>§",$E12))) | T12: =IF($C12="","",SUMIFS(Статистика!$H$7:$H$1006,Статистика!$B$7:$B$1006,">="&($C12-$D$5),Статистика!$B$7:$B$1006,"<="&($C12-1),Статистика!$C$7:$C$1006,IF($D12="","<>§",$D12),Статистика!$D$7:$D$1006,IF($E12="","<>§",$E12))) | U12: =IF($C12="","",SUMIFS(Статистика!$T$7:$T$1006,Статистика!$B$7:$B$1006,">="&($C12-$D$5),Статистика!$B$7:$B$1006,"<="&($C12-1),Статистика!$C$7:$C$1006,IF($D12="","<>§",$D12),Статистика!$D$7:$D$1006,IF($E12="","<>§",$E12))) | V12: =IF($C12="","",SUMIFS(Статистика!$E$7:$E$1006,Статистика!$B$7:$B$1006,">="&($C12+1),Статистика!$B$7:$B$1006,"<="&($C12+$D$5),Статистика!$C$7:$C$1006,IF($D12="","<>§",$D12),Статистика!$D$7:$D$1006,IF($E12="","<>§",$E12))) | W12: =IF($C12="","",SUMIFS(Статистика!$H$7:$H$1006,Статистика!$B$7:$B$1006,">="&($C12+1),Статистика!$B$7:$B$1006,"<="&($C12+$D$5),Статистика!$C$7:$C$1006,IF($D12="","<>§",$D12),Статистика!$D$7:$D$1006,IF($E12="","<>§",$E12))) | X12: =IF($C12="","",SUMIFS(Статистика!$T$7:$T$1006,Статистика!$B$7:$B$1006,">="&($C12+1),Статистика!$B$7:$B$1006,"<="&($C12+$D$5),Статистика!$C$7:$C$1006,IF($D12="","<>§",$D12),Статистика!$D$7:$D$1006,IF($E12="","<>§",$E12)))
B13: =IF($C13="","",ROW()-8) | I13: =IF($C13="","",IFERROR(S13/T13,"—")) | J13: =IF($C13="","",IFERROR(V13/W13,"—")) | K13: =IF($C13="","",IFERROR(J13/I13-1,"")) | L13: =IF($C13="","",IFERROR((U13-S13)/S13,"—")) | M13: =IF($C13="","",IFERROR((X13-V13)/V13,"—")) | N13: =IF($C13="","",T13/$D$5) | O13: =IF($C13="","",W13/$D$5) | P13: =IF($C13="","",IF(MAX(Статистика!$B$7:$B$1006)<$C13+$D$5,"Чекаємо даних",IF(S13=0,"Новий (без бази)",IF(OR(T13=0,W13=0),"Мало даних",IF(K13<=-$F$5,"Покращило",IF(K13>=$F$5,"Погіршило","Без змін")))))) | S13: =IF($C13="","",SUMIFS(Статистика!$E$7:$E$1006,Статистика!$B$7:$B$1006,">="&($C13-$D$5),Статистика!$B$7:$B$1006,"<="&($C13-1),Статистика!$C$7:$C$1006,IF($D13="","<>§",$D13),Статистика!$D$7:$D$1006,IF($E13="","<>§",$E13))) | T13: =IF($C13="","",SUMIFS(Статистика!$H$7:$H$1006,Статистика!$B$7:$B$1006,">="&($C13-$D$5),Статистика!$B$7:$B$1006,"<="&($C13-1),Статистика!$C$7:$C$1006,IF($D13="","<>§",$D13),Статистика!$D$7:$D$1006,IF($E13="","<>§",$E13))) | U13: =IF($C13="","",SUMIFS(Статистика!$T$7:$T$1006,Статистика!$B$7:$B$1006,">="&($C13-$D$5),Статистика!$B$7:$B$1006,"<="&($C13-1),Статистика!$C$7:$C$1006,IF($D13="","<>§",$D13),Статистика!$D$7:$D$1006,IF($E13="","<>§",$E13))) | V13: =IF($C13="","",SUMIFS(Статистика!$E$7:$E$1006,Статистика!$B$7:$B$1006,">="&($C13+1),Статистика!$B$7:$B$1006,"<="&($C13+$D$5),Статистика!$C$7:$C$1006,IF($D13="","<>§",$D13),Статистика!$D$7:$D$1006,IF($E13="","<>§",$E13))) | W13: =IF($C13="","",SUMIFS(Статистика!$H$7:$H$1006,Статистика!$B$7:$B$1006,">="&($C13+1),Статистика!$B$7:$B$1006,"<="&($C13+$D$5),Статистика!$C$7:$C$1006,IF($D13="","<>§",$D13),Статистика!$D$7:$D$1006,IF($E13="","<>§",$E13))) | X13: =IF($C13="","",SUMIFS(Статистика!$T$7:$T$1006,Статистика!$B$7:$B$1006,">="&($C13+1),Статистика!$B$7:$B$1006,"<="&($C13+$D$5),Статистика!$C$7:$C$1006,IF($D13="","<>§",$D13),Статистика!$D$7:$D$1006,IF($E13="","<>§",$E13)))
B14: =IF($C14="","",ROW()-8) | I14: =IF($C14="","",IFERROR(S14/T14,"—")) | J14: =IF($C14="","",IFERROR(V14/W14,"—")) | K14: =IF($C14="","",IFERROR(J14/I14-1,"")) | L14: =IF($C14="","",IFERROR((U14-S14)/S14,"—")) | M14: =IF($C14="","",IFERROR((X14-V14)/V14,"—")) | N14: =IF($C14="","",T14/$D$5) | O14: =IF($C14="","",W14/$D$5) | P14: =IF($C14="","",IF(MAX(Статистика!$B$7:$B$1006)<$C14+$D$5,"Чекаємо даних",IF(S14=0,"Новий (без бази)",IF(OR(T14=0,W14=0),"Мало даних",IF(K14<=-$F$5,"Покращило",IF(K14>=$F$5,"Погіршило","Без змін")))))) | S14: =IF($C14="","",SUMIFS(Статистика!$E$7:$E$1006,Статистика!$B$7:$B$1006,">="&($C14-$D$5),Статистика!$B$7:$B$1006,"<="&($C14-1),Статистика!$C$7:$C$1006,IF($D14="","<>§",$D14),Статистика!$D$7:$D$1006,IF($E14="","<>§",$E14))) | T14: =IF($C14="","",SUMIFS(Статистика!$H$7:$H$1006,Статистика!$B$7:$B$1006,">="&($C14-$D$5),Статистика!$B$7:$B$1006,"<="&($C14-1),Статистика!$C$7:$C$1006,IF($D14="","<>§",$D14),Статистика!$D$7:$D$1006,IF($E14="","<>§",$E14))) | U14: =IF($C14="","",SUMIFS(Статистика!$T$7:$T$1006,Статистика!$B$7:$B$1006,">="&($C14-$D$5),Статистика!$B$7:$B$1006,"<="&($C14-1),Статистика!$C$7:$C$1006,IF($D14="","<>§",$D14),Статистика!$D$7:$D$1006,IF($E14="","<>§",$E14))) | V14: =IF($C14="","",SUMIFS(Статистика!$E$7:$E$1006,Статистика!$B$7:$B$1006,">="&($C14+1),Статистика!$B$7:$B$1006,"<="&($C14+$D$5),Статистика!$C$7:$C$1006,IF($D14="","<>§",$D14),Статистика!$D$7:$D$1006,IF($E14="","<>§",$E14))) | W14: =IF($C14="","",SUMIFS(Статистика!$H$7:$H$1006,Статистика!$B$7:$B$1006,">="&($C14+1),Статистика!$B$7:$B$1006,"<="&($C14+$D$5),Статистика!$C$7:$C$1006,IF($D14="","<>§",$D14),Статистика!$D$7:$D$1006,IF($E14="","<>§",$E14))) | X14: =IF($C14="","",SUMIFS(Статистика!$T$7:$T$1006,Статистика!$B$7:$B$1006,">="&($C14+1),Статистика!$B$7:$B$1006,"<="&($C14+$D$5),Статистика!$C$7:$C$1006,IF($D14="","<>§",$D14),Статистика!$D$7:$D$1006,IF($E14="","<>§",$E14)))
B15: =IF($C15="","",ROW()-8) | I15: =IF($C15="","",IFERROR(S15/T15,"—")) | J15: =IF($C15="","",IFERROR(V15/W15,"—")) | K15: =IF($C15="","",IFERROR(J15/I15-1,"")) | L15: =IF($C15="","",IFERROR((U15-S15)/S15,"—")) | M15: =IF($C15="","",IFERROR((X15-V15)/V15,"—")) | N15: =IF($C15="","",T15/$D$5) | O15: =IF($C15="","",W15/$D$5) | P15: =IF($C15="","",IF(MAX(Статистика!$B$7:$B$1006)<$C15+$D$5,"Чекаємо даних",IF(S15=0,"Новий (без бази)",IF(OR(T15=0,W15=0),"Мало даних",IF(K15<=-$F$5,"Покращило",IF(K15>=$F$5,"Погіршило","Без змін")))))) | S15: =IF($C15="","",SUMIFS(Статистика!$E$7:$E$1006,Статистика!$B$7:$B$1006,">="&($C15-$D$5),Статистика!$B$7:$B$1006,"<="&($C15-1),Статистика!$C$7:$C$1006,IF($D15="","<>§",$D15),Статистика!$D$7:$D$1006,IF($E15="","<>§",$E15))) | T15: =IF($C15="","",SUMIFS(Статистика!$H$7:$H$1006,Статистика!$B$7:$B$1006,">="&($C15-$D$5),Статистика!$B$7:$B$1006,"<="&($C15-1),Статистика!$C$7:$C$1006,IF($D15="","<>§",$D15),Статистика!$D$7:$D$1006,IF($E15="","<>§",$E15))) | U15: =IF($C15="","",SUMIFS(Статистика!$T$7:$T$1006,Статистика!$B$7:$B$1006,">="&($C15-$D$5),Статистика!$B$7:$B$1006,"<="&($C15-1),Статистика!$C$7:$C$1006,IF($D15="","<>§",$D15),Статистика!$D$7:$D$1006,IF($E15="","<>§",$E15))) | V15: =IF($C15="","",SUMIFS(Статистика!$E$7:$E$1006,Статистика!$B$7:$B$1006,">="&($C15+1),Статистика!$B$7:$B$1006,"<="&($C15+$D$5),Статистика!$C$7:$C$1006,IF($D15="","<>§",$D15),Статистика!$D$7:$D$1006,IF($E15="","<>§",$E15))) | W15: =IF($C15="","",SUMIFS(Статистика!$H$7:$H$1006,Статистика!$B$7:$B$1006,">="&($C15+1),Статистика!$B$7:$B$1006,"<="&($C15+$D$5),Статистика!$C$7:$C$1006,IF($D15="","<>§",$D15),Статистика!$D$7:$D$1006,IF($E15="","<>§",$E15))) | X15: =IF($C15="","",SUMIFS(Статистика!$T$7:$T$1006,Статистика!$B$7:$B$1006,">="&($C15+1),Статистика!$B$7:$B$1006,"<="&($C15+$D$5),Статистика!$C$7:$C$1006,IF($D15="","<>§",$D15),Статистика!$D$7:$D$1006,IF($E15="","<>§",$E15)))
B16: =IF($C16="","",ROW()-8) | I16: =IF($C16="","",IFERROR(S16/T16,"—")) | J16: =IF($C16="","",IFERROR(V16/W16,"—")) | K16: =IF($C16="","",IFERROR(J16/I16-1,"")) | L16: =IF($C16="","",IFERROR((U16-S16)/S16,"—")) | M16: =IF($C16="","",IFERROR((X16-V16)/V16,"—")) | N16: =IF($C16="","",T16/$D$5) | O16: =IF($C16="","",W16/$D$5) | P16: =IF($C16="","",IF(MAX(Статистика!$B$7:$B$1006)<$C16+$D$5,"Чекаємо даних",IF(S16=0,"Новий (без бази)",IF(OR(T16=0,W16=0),"Мало даних",IF(K16<=-$F$5,"Покращило",IF(K16>=$F$5,"Погіршило","Без змін")))))) | S16: =IF($C16="","",SUMIFS(Статистика!$E$7:$E$1006,Статистика!$B$7:$B$1006,">="&($C16-$D$5),Статистика!$B$7:$B$1006,"<="&($C16-1),Статистика!$C$7:$C$1006,IF($D16="","<>§",$D16),Статистика!$D$7:$D$1006,IF($E16="","<>§",$E16))) | T16: =IF($C16="","",SUMIFS(Статистика!$H$7:$H$1006,Статистика!$B$7:$B$1006,">="&($C16-$D$5),Статистика!$B$7:$B$1006,"<="&($C16-1),Статистика!$C$7:$C$1006,IF($D16="","<>§",$D16),Статистика!$D$7:$D$1006,IF($E16="","<>§",$E16))) | U16: =IF($C16="","",SUMIFS(Статистика!$T$7:$T$1006,Статистика!$B$7:$B$1006,">="&($C16-$D$5),Статистика!$B$7:$B$1006,"<="&($C16-1),Статистика!$C$7:$C$1006,IF($D16="","<>§",$D16),Статистика!$D$7:$D$1006,IF($E16="","<>§",$E16))) | V16: =IF($C16="","",SUMIFS(Статистика!$E$7:$E$1006,Статистика!$B$7:$B$1006,">="&($C16+1),Статистика!$B$7:$B$1006,"<="&($C16+$D$5),Статистика!$C$7:$C$1006,IF($D16="","<>§",$D16),Статистика!$D$7:$D$1006,IF($E16="","<>§",$E16))) | W16: =IF($C16="","",SUMIFS(Статистика!$H$7:$H$1006,Статистика!$B$7:$B$1006,">="&($C16+1),Статистика!$B$7:$B$1006,"<="&($C16+$D$5),Статистика!$C$7:$C$1006,IF($D16="","<>§",$D16),Статистика!$D$7:$D$1006,IF($E16="","<>§",$E16))) | X16: =IF($C16="","",SUMIFS(Статистика!$T$7:$T$1006,Статистика!$B$7:$B$1006,">="&($C16+1),Статистика!$B$7:$B$1006,"<="&($C16+$D$5),Статистика!$C$7:$C$1006,IF($D16="","<>§",$D16),Статистика!$D$7:$D$1006,IF($E16="","<>§",$E16)))
B17: =IF($C17="","",ROW()-8) | I17: =IF($C17="","",IFERROR(S17/T17,"—")) | J17: =IF($C17="","",IFERROR(V17/W17,"—")) | K17: =IF($C17="","",IFERROR(J17/I17-1,"")) | L17: =IF($C17="","",IFERROR((U17-S17)/S17,"—")) | M17: =IF($C17="","",IFERROR((X17-V17)/V17,"—")) | N17: =IF($C17="","",T17/$D$5) | O17: =IF($C17="","",W17/$D$5) | P17: =IF($C17="","",IF(MAX(Статистика!$B$7:$B$1006)<$C17+$D$5,"Чекаємо даних",IF(S17=0,"Новий (без бази)",IF(OR(T17=0,W17=0),"Мало даних",IF(K17<=-$F$5,"Покращило",IF(K17>=$F$5,"Погіршило","Без змін")))))) | S17: =IF($C17="","",SUMIFS(Статистика!$E$7:$E$1006,Статистика!$B$7:$B$1006,">="&($C17-$D$5),Статистика!$B$7:$B$1006,"<="&($C17-1),Статистика!$C$7:$C$1006,IF($D17="","<>§",$D17),Статистика!$D$7:$D$1006,IF($E17="","<>§",$E17))) | T17: =IF($C17="","",SUMIFS(Статистика!$H$7:$H$1006,Статистика!$B$7:$B$1006,">="&($C17-$D$5),Статистика!$B$7:$B$1006,"<="&($C17-1),Статистика!$C$7:$C$1006,IF($D17="","<>§",$D17),Статистика!$D$7:$D$1006,IF($E17="","<>§",$E17))) | U17: =IF($C17="","",SUMIFS(Статистика!$T$7:$T$1006,Статистика!$B$7:$B$1006,">="&($C17-$D$5),Статистика!$B$7:$B$1006,"<="&($C17-1),Статистика!$C$7:$C$1006,IF($D17="","<>§",$D17),Статистика!$D$7:$D$1006,IF($E17="","<>§",$E17))) | V17: =IF($C17="","",SUMIFS(Статистика!$E$7:$E$1006,Статистика!$B$7:$B$1006,">="&($C17+1),Статистика!$B$7:$B$1006,"<="&($C17+$D$5),Статистика!$C$7:$C$1006,IF($D17="","<>§",$D17),Статистика!$D$7:$D$1006,IF($E17="","<>§",$E17))) | W17: =IF($C17="","",SUMIFS(Статистика!$H$7:$H$1006,Статистика!$B$7:$B$1006,">="&($C17+1),Статистика!$B$7:$B$1006,"<="&($C17+$D$5),Статистика!$C$7:$C$1006,IF($D17="","<>§",$D17),Статистика!$D$7:$D$1006,IF($E17="","<>§",$E17))) | X17: =IF($C17="","",SUMIFS(Статистика!$T$7:$T$1006,Статистика!$B$7:$B$1006,">="&($C17+1),Статистика!$B$7:$B$1006,"<="&($C17+$D$5),Статистика!$C$7:$C$1006,IF($D17="","<>§",$D17),Статистика!$D$7:$D$1006,IF($E17="","<>§",$E17)))
B18: =IF($C18="","",ROW()-8) | I18: =IF($C18="","",IFERROR(S18/T18,"—")) | J18: =IF($C18="","",IFERROR(V18/W18,"—")) | K18: =IF($C18="","",IFERROR(J18/I18-1,"")) | L18: =IF($C18="","",IFERROR((U18-S18)/S18,"—")) | M18: =IF($C18="","",IFERROR((X18-V18)/V18,"—")) | N18: =IF($C18="","",T18/$D$5) | O18: =IF($C18="","",W18/$D$5) | P18: =IF($C18="","",IF(MAX(Статистика!$B$7:$B$1006)<$C18+$D$5,"Чекаємо даних",IF(S18=0,"Новий (без бази)",IF(OR(T18=0,W18=0),"Мало даних",IF(K18<=-$F$5,"Покращило",IF(K18>=$F$5,"Погіршило","Без змін")))))) | S18: =IF($C18="","",SUMIFS(Статистика!$E$7:$E$1006,Статистика!$B$7:$B$1006,">="&($C18-$D$5),Статистика!$B$7:$B$1006,"<="&($C18-1),Статистика!$C$7:$C$1006,IF($D18="","<>§",$D18),Статистика!$D$7:$D$1006,IF($E18="","<>§",$E18))) | T18: =IF($C18="","",SUMIFS(Статистика!$H$7:$H$1006,Статистика!$B$7:$B$1006,">="&($C18-$D$5),Статистика!$B$7:$B$1006,"<="&($C18-1),Статистика!$C$7:$C$1006,IF($D18="","<>§",$D18),Статистика!$D$7:$D$1006,IF($E18="","<>§",$E18))) | U18: =IF($C18="","",SUMIFS(Статистика!$T$7:$T$1006,Статистика!$B$7:$B$1006,">="&($C18-$D$5),Статистика!$B$7:$B$1006,"<="&($C18-1),Статистика!$C$7:$C$1006,IF($D18="","<>§",$D18),Статистика!$D$7:$D$1006,IF($E18="","<>§",$E18))) | V18: =IF($C18="","",SUMIFS(Статистика!$E$7:$E$1006,Статистика!$B$7:$B$1006,">="&($C18+1),Статистика!$B$7:$B$1006,"<="&($C18+$D$5),Статистика!$C$7:$C$1006,IF($D18="","<>§",$D18),Статистика!$D$7:$D$1006,IF($E18="","<>§",$E18))) | W18: =IF($C18="","",SUMIFS(Статистика!$H$7:$H$1006,Статистика!$B$7:$B$1006,">="&($C18+1),Статистика!$B$7:$B$1006,"<="&($C18+$D$5),Статистика!$C$7:$C$1006,IF($D18="","<>§",$D18),Статистика!$D$7:$D$1006,IF($E18="","<>§",$E18))) | X18: =IF($C18="","",SUMIFS(Статистика!$T$7:$T$1006,Статистика!$B$7:$B$1006,">="&($C18+1),Статистика!$B$7:$B$1006,"<="&($C18+$D$5),Статистика!$C$7:$C$1006,IF($D18="","<>§",$D18),Статистика!$D$7:$D$1006,IF($E18="","<>§",$E18)))
B19: =IF($C19="","",ROW()-8) | I19: =IF($C19="","",IFERROR(S19/T19,"—")) | J19: =IF($C19="","",IFERROR(V19/W19,"—")) | K19: =IF($C19="","",IFERROR(J19/I19-1,"")) | L19: =IF($C19="","",IFERROR((U19-S19)/S19,"—")) | M19: =IF($C19="","",IFERROR((X19-V19)/V19,"—")) | N19: =IF($C19="","",T19/$D$5) | O19: =IF($C19="","",W19/$D$5) | P19: =IF($C19="","",IF(MAX(Статистика!$B$7:$B$1006)<$C19+$D$5,"Чекаємо даних",IF(S19=0,"Новий (без бази)",IF(OR(T19=0,W19=0),"Мало даних",IF(K19<=-$F$5,"Покращило",IF(K19>=$F$5,"Погіршило","Без змін")))))) | S19: =IF($C19="","",SUMIFS(Статистика!$E$7:$E$1006,Статистика!$B$7:$B$1006,">="&($C19-$D$5),Статистика!$B$7:$B$1006,"<="&($C19-1),Статистика!$C$7:$C$1006,IF($D19="","<>§",$D19),Статистика!$D$7:$D$1006,IF($E19="","<>§",$E19))) | T19: =IF($C19="","",SUMIFS(Статистика!$H$7:$H$1006,Статистика!$B$7:$B$1006,">="&($C19-$D$5),Статистика!$B$7:$B$1006,"<="&($C19-1),Статистика!$C$7:$C$1006,IF($D19="","<>§",$D19),Статистика!$D$7:$D$1006,IF($E19="","<>§",$E19))) | U19: =IF($C19="","",SUMIFS(Статистика!$T$7:$T$1006,Статистика!$B$7:$B$1006,">="&($C19-$D$5),Статистика!$B$7:$B$1006,"<="&($C19-1),Статистика!$C$7:$C$1006,IF($D19="","<>§",$D19),Статистика!$D$7:$D$1006,IF($E19="","<>§",$E19))) | V19: =IF($C19="","",SUMIFS(Статистика!$E$7:$E$1006,Статистика!$B$7:$B$1006,">="&($C19+1),Статистика!$B$7:$B$1006,"<="&($C19+$D$5),Статистика!$C$7:$C$1006,IF($D19="","<>§",$D19),Статистика!$D$7:$D$1006,IF($E19="","<>§",$E19))) | W19: =IF($C19="","",SUMIFS(Статистика!$H$7:$H$1006,Статистика!$B$7:$B$1006,">="&($C19+1),Статистика!$B$7:$B$1006,"<="&($C19+$D$5),Статистика!$C$7:$C$1006,IF($D19="","<>§",$D19),Статистика!$D$7:$D$1006,IF($E19="","<>§",$E19))) | X19: =IF($C19="","",SUMIFS(Статистика!$T$7:$T$1006,Статистика!$B$7:$B$1006,">="&($C19+1),Статистика!$B$7:$B$1006,"<="&($C19+$D$5),Статистика!$C$7:$C$1006,IF($D19="","<>§",$D19),Статистика!$D$7:$D$1006,IF($E19="","<>§",$E19)))
B20: =IF($C20="","",ROW()-8) | I20: =IF($C20="","",IFERROR(S20/T20,"—")) | J20: =IF($C20="","",IFERROR(V20/W20,"—")) | K20: =IF($C20="","",IFERROR(J20/I20-1,"")) | L20: =IF($C20="","",IFERROR((U20-S20)/S20,"—")) | M20: =IF($C20="","",IFERROR((X20-V20)/V20,"—")) | N20: =IF($C20="","",T20/$D$5) | O20: =IF($C20="","",W20/$D$5) | P20: =IF($C20="","",IF(MAX(Статистика!$B$7:$B$1006)<$C20+$D$5,"Чекаємо даних",IF(S20=0,"Новий (без бази)",IF(OR(T20=0,W20=0),"Мало даних",IF(K20<=-$F$5,"Покращило",IF(K20>=$F$5,"Погіршило","Без змін")))))) | S20: =IF($C20="","",SUMIFS(Статистика!$E$7:$E$1006,Статистика!$B$7:$B$1006,">="&($C20-$D$5),Статистика!$B$7:$B$1006,"<="&($C20-1),Статистика!$C$7:$C$1006,IF($D20="","<>§",$D20),Статистика!$D$7:$D$1006,IF($E20="","<>§",$E20))) | T20: =IF($C20="","",SUMIFS(Статистика!$H$7:$H$1006,Статистика!$B$7:$B$1006,">="&($C20-$D$5),Статистика!$B$7:$B$1006,"<="&($C20-1),Статистика!$C$7:$C$1006,IF($D20="","<>§",$D20),Статистика!$D$7:$D$1006,IF($E20="","<>§",$E20))) | U20: =IF($C20="","",SUMIFS(Статистика!$T$7:$T$1006,Статистика!$B$7:$B$1006,">="&($C20-$D$5),Статистика!$B$7:$B$1006,"<="&($C20-1),Статистика!$C$7:$C$1006,IF($D20="","<>§",$D20),Статистика!$D$7:$D$1006,IF($E20="","<>§",$E20))) | V20: =IF($C20="","",SUMIFS(Статистика!$E$7:$E$1006,Статистика!$B$7:$B$1006,">="&($C20+1),Статистика!$B$7:$B$1006,"<="&($C20+$D$5),Статистика!$C$7:$C$1006,IF($D20="","<>§",$D20),Статистика!$D$7:$D$1006,IF($E20="","<>§",$E20))) | W20: =IF($C20="","",SUMIFS(Статистика!$H$7:$H$1006,Статистика!$B$7:$B$1006,">="&($C20+1),Статистика!$B$7:$B$1006,"<="&($C20+$D$5),Статистика!$C$7:$C$1006,IF($D20="","<>§",$D20),Статистика!$D$7:$D$1006,IF($E20="","<>§",$E20))) | X20: =IF($C20="","",SUMIFS(Статистика!$T$7:$T$1006,Статистика!$B$7:$B$1006,">="&($C20+1),Статистика!$B$7:$B$1006,"<="&($C20+$D$5),Статистика!$C$7:$C$1006,IF($D20="","<>§",$D20),Статистика!$D$7:$D$1006,IF($E20="","<>§",$E20)))
B21: =IF($C21="","",ROW()-8) | I21: =IF($C21="","",IFERROR(S21/T21,"—")) | J21: =IF($C21="","",IFERROR(V21/W21,"—")) | K21: =IF($C21="","",IFERROR(J21/I21-1,"")) | L21: =IF($C21="","",IFERROR((U21-S21)/S21,"—")) | M21: =IF($C21="","",IFERROR((X21-V21)/V21,"—")) | N21: =IF($C21="","",T21/$D$5) | O21: =IF($C21="","",W21/$D$5) | P21: =IF($C21="","",IF(MAX(Статистика!$B$7:$B$1006)<$C21+$D$5,"Чекаємо даних",IF(S21=0,"Новий (без бази)",IF(OR(T21=0,W21=0),"Мало даних",IF(K21<=-$F$5,"Покращило",IF(K21>=$F$5,"Погіршило","Без змін")))))) | S21: =IF($C21="","",SUMIFS(Статистика!$E$7:$E$1006,Статистика!$B$7:$B$1006,">="&($C21-$D$5),Статистика!$B$7:$B$1006,"<="&($C21-1),Статистика!$C$7:$C$1006,IF($D21="","<>§",$D21),Статистика!$D$7:$D$1006,IF($E21="","<>§",$E21))) | T21: =IF($C21="","",SUMIFS(Статистика!$H$7:$H$1006,Статистика!$B$7:$B$1006,">="&($C21-$D$5),Статистика!$B$7:$B$1006,"<="&($C21-1),Статистика!$C$7:$C$1006,IF($D21="","<>§",$D21),Статистика!$D$7:$D$1006,IF($E21="","<>§",$E21))) | U21: =IF($C21="","",SUMIFS(Статистика!$T$7:$T$1006,Статистика!$B$7:$B$1006,">="&($C21-$D$5),Статистика!$B$7:$B$1006,"<="&($C21-1),Статистика!$C$7:$C$1006,IF($D21="","<>§",$D21),Статистика!$D$7:$D$1006,IF($E21="","<>§",$E21))) | V21: =IF($C21="","",SUMIFS(Статистика!$E$7:$E$1006,Статистика!$B$7:$B$1006,">="&($C21+1),Статистика!$B$7:$B$1006,"<="&($C21+$D$5),Статистика!$C$7:$C$1006,IF($D21="","<>§",$D21),Статистика!$D$7:$D$1006,IF($E21="","<>§",$E21))) | W21: =IF($C21="","",SUMIFS(Статистика!$H$7:$H$1006,Статистика!$B$7:$B$1006,">="&($C21+1),Статистика!$B$7:$B$1006,"<="&($C21+$D$5),Статистика!$C$7:$C$1006,IF($D21="","<>§",$D21),Статистика!$D$7:$D$1006,IF($E21="","<>§",$E21))) | X21: =IF($C21="","",SUMIFS(Статистика!$T$7:$T$1006,Статистика!$B$7:$B$1006,">="&($C21+1),Статистика!$B$7:$B$1006,"<="&($C21+$D$5),Статистика!$C$7:$C$1006,IF($D21="","<>§",$D21),Статистика!$D$7:$D$1006,IF($E21="","<>§",$E21)))
... B308: =IF($C308="","",ROW()-8) | I308: =IF($C308="","",IFERROR(S308/T308,"—")) | J308: =IF($C308="","",IFERROR(V308/W308,"—")) | K308: =IF($C308="","",IFERROR(J308/I308-1,"")) | L308: =IF($C308="","",IFERROR((U308-S308)/S308,"—")) | M308: =IF($C308="","",IFERROR((X308-V308)/V308,"—")) | N308: =IF($C308="","",T308/$D$5) | O308: =IF($C308="","",W308/$D$5) | P308: =IF($C308="","",IF(MAX(Статистика!$B$7:$B$1006)<$C308+$D$5,"Чекаємо даних",IF(S308=0,"Новий (без бази)",IF(OR(T308=0,W308=0),"Мало даних",IF(K308<=-$F$5,"Покращило",IF(K308>=$F$5,"Погіршило","Без змін")))))) | S308: =IF($C308="","",SUMIFS(Статистика!$E$7:$E$1006,Статистика!$B$7:$B$1006,">="&($C308-$D$5),Статистика!$B$7:$B$1006,"<="&($C308-1),Статистика!$C$7:$C$1006,IF($D308="","<>§",$D308),Статистика!$D$7:$D$1006,IF($E308="","<>§",$E308))) | T308: =IF($C308="","",SUMIFS(Статистика!$H$7:$H$1006,Статистика!$B$7:$B$1006,">="&($C308-$D$5),Статистика!$B$7:$B$1006,"<="&($C308-1),Статистика!$C$7:$C$1006,IF($D308="","<>§",$D308),Статистика!$D$7:$D$1006,IF($E308="","<>§",$E308))) | U308: =IF($C308="","",SUMIFS(Статистика!$T$7:$T$1006,Статистика!$B$7:$B$1006,">="&($C308-$D$5),Статистика!$B$7:$B$1006,"<="&($C308-1),Статистика!$C$7:$C$1006,IF($D308="","<>§",$D308),Статистика!$D$7:$D$1006,IF($E308="","<>§",$E308))) | V308: =IF($C308="","",SUMIFS(Статистика!$E$7:$E$1006,Статистика!$B$7:$B$1006,">="&($C308+1),Статистика!$B$7:$B$1006,"<="&($C308+$D$5),Статистика!$C$7:$C$1006,IF($D308="","<>§",$D308),Статистика!$D$7:$D$1006,IF($E308="","<>§",$E308))) | W308: =IF($C308="","",SUMIFS(Статистика!$H$7:$H$1006,Статистика!$B$7:$B$1006,">="&($C308+1),Статистика!$B$7:$B$1006,"<="&($C308+$D$5),Статистика!$C$7:$C$1006,IF($D308="","<>§",$D308),Статистика!$D$7:$D$1006,IF($E308="","<>§",$E308))) | X308: =IF($C308="","",SUMIFS(Статистика!$T$7:$T$1006,Статистика!$B$7:$B$1006,">="&($C308+1),Статистика!$B$7:$B$1006,"<="&($C308+$D$5),Статистика!$C$7:$C$1006,IF($D308="","<>§",$D308),Статистика!$D$7:$D$1006,IF($E308="","<>§",$E308)))

Sheet Загальна по днях
B2: Загальна статистика по днях
B3: Всі гео разом, рахується зі «Статистики». За замовчуванням — місяць останнього дня з даними.
B5: СПЕНД | D5: ДОХІД | F5: ПРОФІТ | H5: ROI | J5: ЛІДИ | L5: CPL | N5: АПРУВИ* | P5: ЦІНА АПРУВУ
B6: =SUM(D11:D41) -> 150 | D6: =SUM(I11:I41) -> 224 | F6: =SUM(J11:J41) -> 74 | H6: =IFERROR(SUM(J11:J41)/SUM(D11:D41),"–") -> 0.49333333 | J6: =SUM(G11:G41) -> 21 | L6: =IFERROR(SUM(D11:D41)/SUM(G11:G41),"–") -> 7.1428571 | N6: =SUM(H11:H41) -> 8 | P6: =IFERROR(SUM(D11:D41)/SUM(H11:H41),"–") -> 18.75
B8: Початок періоду | E8: порожньо = поточний місяць з даних; дата = 31 день від неї | L8: Період: | M8: =IF($D$8<>"",$D$8,IF(COUNT(Статистика!$B$7:$B$1006)=0,DATE(YEAR(TODAY()),MONTH(TODAY()),1),DATE(YEAR(MAX(Статистика!$B$7:$B$1006)),MONTH(MAX(Статистика!$B$7:$B$1006)),1))) -> 46296 | O8: — | P8: =IF($D$8<>"",$D$8+30,EOMONTH($M$8,0)) -> 46326
B10: Дата | C10: День | D10: Спенд, $ | E10: Покази | F10: Кліки | G10: Ліди | H10: Апруви* | I10: Дохід, $ | J10: Профіт, $ | K10: ROI | L10: CTR | M10: CPC, $ | N10: CPM, $ | O10: CR | P10: CPL, $ | Q10: Ціна апруву, $ | R10: Профіт наростаючим, $
B11: =$M$8 -> 46296 | C11: =IF($B11="","",CHOOSE(WEEKDAY(B11,2),"Пн","Вт","Ср","Чт","Пт","Сб","Нд")) -> Чт | D11: =IF($B11="","",SUMIFS(Статистика!$E$7:$E$1006,Статистика!$B$7:$B$1006,$B11)) -> 150 | E11: =IF($B11="","",SUMIFS(Статистика!$F$7:$F$1006,Статистика!$B$7:$B$1006,$B11)) -> 20000 | F11: =IF($B11="","",SUMIFS(Статистика!$G$7:$G$1006,Статистика!$B$7:$B$1006,$B11)) -> 420 | G11: =IF($B11="","",SUMIFS(Статистика!$H$7:$H$1006,Статистика!$B$7:$B$1006,$B11)) -> 21 | H11: =IF($B11="","",SUMIFS(Статистика!$Q$7:$Q$1006,Статистика!$B$7:$B$1006,$B11)) -> 8 | I11: =IF($B11="","",SUMIFS(Статистика!$T$7:$T$1006,Статистика!$B$7:$B$1006,$B11)) -> 224 | J11: =IF($B11="","",I11-D11) -> 74 | K11: =IF($B11="","",IFERROR(J11/D11,"")) -> 0.49333333 | L11: =IF($B11="","",IFERROR(F11/E11,"")) -> 0.021 | M11: =IF($B11="","",IFERROR(D11/F11,"")) -> 0.35714286 | N11: =IF($B11="","",IFERROR(D11/E11*1000,"")) -> 7.5 | O11: =IF($B11="","",IFERROR(G11/F11,"")) -> 0.05 | P11: =IF($B11="","",IFERROR(D11/G11,"")) -> 7.1428571 | Q11: =IF($B11="","",IFERROR(D11/H11,"")) -> 18.75 | R11: =IF(OR($B11="",$B11>MAX(Статистика!$B$7:$B$1006)),"",SUM($J$11:J11)) -> 74
B12: =IF(B11="","",IF(B11+1>$P$8,"",B11+1)) -> 46297 | C12: =IF($B12="","",CHOOSE(WEEKDAY(B12,2),"Пн","Вт","Ср","Чт","Пт","Сб","Нд")) -> Пт | D12: =IF($B12="","",SUMIFS(Статистика!$E$7:$E$1006,Статистика!$B$7:$B$1006,$B12)) -> 0 | E12: =IF($B12="","",SUMIFS(Статистика!$F$7:$F$1006,Статистика!$B$7:$B$1006,$B12)) -> 0 | F12: =IF($B12="","",SUMIFS(Статистика!$G$7:$G$1006,Статистика!$B$7:$B$1006,$B12)) -> 0 | G12: =IF($B12="","",SUMIFS(Статистика!$H$7:$H$1006,Статистика!$B$7:$B$1006,$B12)) -> 0 | H12: =IF($B12="","",SUMIFS(Статистика!$Q$7:$Q$1006,Статистика!$B$7:$B$1006,$B12)) -> 0 | I12: =IF($B12="","",SUMIFS(Статистика!$T$7:$T$1006,Статистика!$B$7:$B$1006,$B12)) -> 0 | J12: =IF($B12="","",I12-D12) -> 0 | K12: =IF($B12="","",IFERROR(J12/D12,"")) | L12: =IF($B12="","",IFERROR(F12/E12,"")) | M12: =IF($B12="","",IFERROR(D12/F12,"")) | N12: =IF($B12="","",IFERROR(D12/E12*1000,"")) | O12: =IF($B12="","",IFERROR(G12/F12,"")) | P12: =IF($B12="","",IFERROR(D12/G12,"")) | Q12: =IF($B12="","",IFERROR(D12/H12,"")) | R12: =IF(OR($B12="",$B12>MAX(Статистика!$B$7:$B$1006)),"",SUM($J$11:J12))
B13: =IF(B12="","",IF(B12+1>$P$8,"",B12+1)) -> 46298 | C13: =IF($B13="","",CHOOSE(WEEKDAY(B13,2),"Пн","Вт","Ср","Чт","Пт","Сб","Нд")) -> Сб | D13: =IF($B13="","",SUMIFS(Статистика!$E$7:$E$1006,Статистика!$B$7:$B$1006,$B13)) -> 0 | E13: =IF($B13="","",SUMIFS(Статистика!$F$7:$F$1006,Статистика!$B$7:$B$1006,$B13)) -> 0 | F13: =IF($B13="","",SUMIFS(Статистика!$G$7:$G$1006,Статистика!$B$7:$B$1006,$B13)) -> 0 | G13: =IF($B13="","",SUMIFS(Статистика!$H$7:$H$1006,Статистика!$B$7:$B$1006,$B13)) -> 0 | H13: =IF($B13="","",SUMIFS(Статистика!$Q$7:$Q$1006,Статистика!$B$7:$B$1006,$B13)) -> 0 | I13: =IF($B13="","",SUMIFS(Статистика!$T$7:$T$1006,Статистика!$B$7:$B$1006,$B13)) -> 0 | J13: =IF($B13="","",I13-D13) -> 0 | K13: =IF($B13="","",IFERROR(J13/D13,"")) | L13: =IF($B13="","",IFERROR(F13/E13,"")) | M13: =IF($B13="","",IFERROR(D13/F13,"")) | N13: =IF($B13="","",IFERROR(D13/E13*1000,"")) | O13: =IF($B13="","",IFERROR(G13/F13,"")) | P13: =IF($B13="","",IFERROR(D13/G13,"")) | Q13: =IF($B13="","",IFERROR(D13/H13,"")) | R13: =IF(OR($B13="",$B13>MAX(Статистика!$B$7:$B$1006)),"",SUM($J$11:J13))
B14: =IF(B13="","",IF(B13+1>$P$8,"",B13+1)) -> 46299 | C14: =IF($B14="","",CHOOSE(WEEKDAY(B14,2),"Пн","Вт","Ср","Чт","Пт","Сб","Нд")) -> Нд | D14: =IF($B14="","",SUMIFS(Статистика!$E$7:$E$1006,Статистика!$B$7:$B$1006,$B14)) -> 0 | E14: =IF($B14="","",SUMIFS(Статистика!$F$7:$F$1006,Статистика!$B$7:$B$1006,$B14)) -> 0 | F14: =IF($B14="","",SUMIFS(Статистика!$G$7:$G$1006,Статистика!$B$7:$B$1006,$B14)) -> 0 | G14: =IF($B14="","",SUMIFS(Статистика!$H$7:$H$1006,Статистика!$B$7:$B$1006,$B14)) -> 0 | H14: =IF($B14="","",SUMIFS(Статистика!$Q$7:$Q$1006,Статистика!$B$7:$B$1006,$B14)) -> 0 | I14: =IF($B14="","",SUMIFS(Статистика!$T$7:$T$1006,Статистика!$B$7:$B$1006,$B14)) -> 0 | J14: =IF($B14="","",I14-D14) -> 0 | K14: =IF($B14="","",IFERROR(J14/D14,"")) | L14: =IF($B14="","",IFERROR(F14/E14,"")) | M14: =IF($B14="","",IFERROR(D14/F14,"")) | N14: =IF($B14="","",IFERROR(D14/E14*1000,"")) | O14: =IF($B14="","",IFERROR(G14/F14,"")) | P14: =IF($B14="","",IFERROR(D14/G14,"")) | Q14: =IF($B14="","",IFERROR(D14/H14,"")) | R14: =IF(OR($B14="",$B14>MAX(Статистика!$B$7:$B$1006)),"",SUM($J$11:J14))
B15: =IF(B14="","",IF(B14+1>$P$8,"",B14+1)) -> 46300 | C15: =IF($B15="","",CHOOSE(WEEKDAY(B15,2),"Пн","Вт","Ср","Чт","Пт","Сб","Нд")) -> Пн | D15: =IF($B15="","",SUMIFS(Статистика!$E$7:$E$1006,Статистика!$B$7:$B$1006,$B15)) -> 0 | E15: =IF($B15="","",SUMIFS(Статистика!$F$7:$F$1006,Статистика!$B$7:$B$1006,$B15)) -> 0 | F15: =IF($B15="","",SUMIFS(Статистика!$G$7:$G$1006,Статистика!$B$7:$B$1006,$B15)) -> 0 | G15: =IF($B15="","",SUMIFS(Статистика!$H$7:$H$1006,Статистика!$B$7:$B$1006,$B15)) -> 0 | H15: =IF($B15="","",SUMIFS(Статистика!$Q$7:$Q$1006,Статистика!$B$7:$B$1006,$B15)) -> 0 | I15: =IF($B15="","",SUMIFS(Статистика!$T$7:$T$1006,Статистика!$B$7:$B$1006,$B15)) -> 0 | J15: =IF($B15="","",I15-D15) -> 0 | K15: =IF($B15="","",IFERROR(J15/D15,"")) | L15: =IF($B15="","",IFERROR(F15/E15,"")) | M15: =IF($B15="","",IFERROR(D15/F15,"")) | N15: =IF($B15="","",IFERROR(D15/E15*1000,"")) | O15: =IF($B15="","",IFERROR(G15/F15,"")) | P15: =IF($B15="","",IFERROR(D15/G15,"")) | Q15: =IF($B15="","",IFERROR(D15/H15,"")) | R15: =IF(OR($B15="",$B15>MAX(Статистика!$B$7:$B$1006)),"",SUM($J$11:J15))
B16: =IF(B15="","",IF(B15+1>$P$8,"",B15+1)) -> 46301 | C16: =IF($B16="","",CHOOSE(WEEKDAY(B16,2),"Пн","Вт","Ср","Чт","Пт","Сб","Нд")) -> Вт | D16: =IF($B16="","",SUMIFS(Статистика!$E$7:$E$1006,Статистика!$B$7:$B$1006,$B16)) -> 0 | E16: =IF($B16="","",SUMIFS(Статистика!$F$7:$F$1006,Статистика!$B$7:$B$1006,$B16)) -> 0 | F16: =IF($B16="","",SUMIFS(Статистика!$G$7:$G$1006,Статистика!$B$7:$B$1006,$B16)) -> 0 | G16: =IF($B16="","",SUMIFS(Статистика!$H$7:$H$1006,Статистика!$B$7:$B$1006,$B16)) -> 0 | H16: =IF($B16="","",SUMIFS(Статистика!$Q$7:$Q$1006,Статистика!$B$7:$B$1006,$B16)) -> 0 | I16: =IF($B16="","",SUMIFS(Статистика!$T$7:$T$1006,Статистика!$B$7:$B$1006,$B16)) -> 0 | J16: =IF($B16="","",I16-D16) -> 0 | K16: =IF($B16="","",IFERROR(J16/D16,"")) | L16: =IF($B16="","",IFERROR(F16/E16,"")) | M16: =IF($B16="","",IFERROR(D16/F16,"")) | N16: =IF($B16="","",IFERROR(D16/E16*1000,"")) | O16: =IF($B16="","",IFERROR(G16/F16,"")) | P16: =IF($B16="","",IFERROR(D16/G16,"")) | Q16: =IF($B16="","",IFERROR(D16/H16,"")) | R16: =IF(OR($B16="",$B16>MAX(Статистика!$B$7:$B$1006)),"",SUM($J$11:J16))
B17: =IF(B16="","",IF(B16+1>$P$8,"",B16+1)) -> 46302 | C17: =IF($B17="","",CHOOSE(WEEKDAY(B17,2),"Пн","Вт","Ср","Чт","Пт","Сб","Нд")) -> Ср | D17: =IF($B17="","",SUMIFS(Статистика!$E$7:$E$1006,Статистика!$B$7:$B$1006,$B17)) -> 0 | E17: =IF($B17="","",SUMIFS(Статистика!$F$7:$F$1006,Статистика!$B$7:$B$1006,$B17)) -> 0 | F17: =IF($B17="","",SUMIFS(Статистика!$G$7:$G$1006,Статистика!$B$7:$B$1006,$B17)) -> 0 | G17: =IF($B17="","",SUMIFS(Статистика!$H$7:$H$1006,Статистика!$B$7:$B$1006,$B17)) -> 0 | H17: =IF($B17="","",SUMIFS(Статистика!$Q$7:$Q$1006,Статистика!$B$7:$B$1006,$B17)) -> 0 | I17: =IF($B17="","",SUMIFS(Статистика!$T$7:$T$1006,Статистика!$B$7:$B$1006,$B17)) -> 0 | J17: =IF($B17="","",I17-D17) -> 0 | K17: =IF($B17="","",IFERROR(J17/D17,"")) | L17: =IF($B17="","",IFERROR(F17/E17,"")) | M17: =IF($B17="","",IFERROR(D17/F17,"")) | N17: =IF($B17="","",IFERROR(D17/E17*1000,"")) | O17: =IF($B17="","",IFERROR(G17/F17,"")) | P17: =IF($B17="","",IFERROR(D17/G17,"")) | Q17: =IF($B17="","",IFERROR(D17/H17,"")) | R17: =IF(OR($B17="",$B17>MAX(Статистика!$B$7:$B$1006)),"",SUM($J$11:J17))
B18: =IF(B17="","",IF(B17+1>$P$8,"",B17+1)) -> 46303 | C18: =IF($B18="","",CHOOSE(WEEKDAY(B18,2),"Пн","Вт","Ср","Чт","Пт","Сб","Нд")) -> Чт | D18: =IF($B18="","",SUMIFS(Статистика!$E$7:$E$1006,Статистика!$B$7:$B$1006,$B18)) -> 0 | E18: =IF($B18="","",SUMIFS(Статистика!$F$7:$F$1006,Статистика!$B$7:$B$1006,$B18)) -> 0 | F18: =IF($B18="","",SUMIFS(Статистика!$G$7:$G$1006,Статистика!$B$7:$B$1006,$B18)) -> 0 | G18: =IF($B18="","",SUMIFS(Статистика!$H$7:$H$1006,Статистика!$B$7:$B$1006,$B18)) -> 0 | H18: =IF($B18="","",SUMIFS(Статистика!$Q$7:$Q$1006,Статистика!$B$7:$B$1006,$B18)) -> 0 | I18: =IF($B18="","",SUMIFS(Статистика!$T$7:$T$1006,Статистика!$B$7:$B$1006,$B18)) -> 0 | J18: =IF($B18="","",I18-D18) -> 0 | K18: =IF($B18="","",IFERROR(J18/D18,"")) | L18: =IF($B18="","",IFERROR(F18/E18,"")) | M18: =IF($B18="","",IFERROR(D18/F18,"")) | N18: =IF($B18="","",IFERROR(D18/E18*1000,"")) | O18: =IF($B18="","",IFERROR(G18/F18,"")) | P18: =IF($B18="","",IFERROR(D18/G18,"")) | Q18: =IF($B18="","",IFERROR(D18/H18,"")) | R18: =IF(OR($B18="",$B18>MAX(Статистика!$B$7:$B$1006)),"",SUM($J$11:J18))
B19: =IF(B18="","",IF(B18+1>$P$8,"",B18+1)) -> 46304 | C19: =IF($B19="","",CHOOSE(WEEKDAY(B19,2),"Пн","Вт","Ср","Чт","Пт","Сб","Нд")) -> Пт | D19: =IF($B19="","",SUMIFS(Статистика!$E$7:$E$1006,Статистика!$B$7:$B$1006,$B19)) -> 0 | E19: =IF($B19="","",SUMIFS(Статистика!$F$7:$F$1006,Статистика!$B$7:$B$1006,$B19)) -> 0 | F19: =IF($B19="","",SUMIFS(Статистика!$G$7:$G$1006,Статистика!$B$7:$B$1006,$B19)) -> 0 | G19: =IF($B19="","",SUMIFS(Статистика!$H$7:$H$1006,Статистика!$B$7:$B$1006,$B19)) -> 0 | H19: =IF($B19="","",SUMIFS(Статистика!$Q$7:$Q$1006,Статистика!$B$7:$B$1006,$B19)) -> 0 | I19: =IF($B19="","",SUMIFS(Статистика!$T$7:$T$1006,Статистика!$B$7:$B$1006,$B19)) -> 0 | J19: =IF($B19="","",I19-D19) -> 0 | K19: =IF($B19="","",IFERROR(J19/D19,"")) | L19: =IF($B19="","",IFERROR(F19/E19,"")) | M19: =IF($B19="","",IFERROR(D19/F19,"")) | N19: =IF($B19="","",IFERROR(D19/E19*1000,"")) | O19: =IF($B19="","",IFERROR(G19/F19,"")) | P19: =IF($B19="","",IFERROR(D19/G19,"")) | Q19: =IF($B19="","",IFERROR(D19/H19,"")) | R19: =IF(OR($B19="",$B19>MAX(Статистика!$B$7:$B$1006)),"",SUM($J$11:J19))
